[2022-12-01T06:01:32.950+0000] {taskinstance.py:1165} INFO - Dependencies all met for <TaskInstance: data_ingestion_gcs_dag.local_to_gcs_task scheduled__2022-11-30T00:00:00+00:00 [queued]>
[2022-12-01T06:01:32.966+0000] {taskinstance.py:1165} INFO - Dependencies all met for <TaskInstance: data_ingestion_gcs_dag.local_to_gcs_task scheduled__2022-11-30T00:00:00+00:00 [queued]>
[2022-12-01T06:01:32.966+0000] {taskinstance.py:1362} INFO - 
--------------------------------------------------------------------------------
[2022-12-01T06:01:32.966+0000] {taskinstance.py:1363} INFO - Starting attempt 1 of 2
[2022-12-01T06:01:32.966+0000] {taskinstance.py:1364} INFO - 
--------------------------------------------------------------------------------
[2022-12-01T06:01:32.985+0000] {taskinstance.py:1383} INFO - Executing <Task(PythonOperator): local_to_gcs_task> on 2022-11-30 00:00:00+00:00
[2022-12-01T06:01:32.994+0000] {standard_task_runner.py:55} INFO - Started process 5823 to run task
[2022-12-01T06:01:33.001+0000] {standard_task_runner.py:82} INFO - Running: ['***', 'tasks', 'run', 'data_ingestion_gcs_dag', 'local_to_gcs_task', 'scheduled__2022-11-30T00:00:00+00:00', '--job-id', '8', '--raw', '--subdir', 'DAGS_FOLDER/data_ingestion_gcs_dag.py', '--cfg-path', '/tmp/tmpuhhtjaxc']
[2022-12-01T06:01:33.004+0000] {standard_task_runner.py:83} INFO - Job 8: Subtask local_to_gcs_task
[2022-12-01T06:01:33.100+0000] {task_command.py:376} INFO - Running <TaskInstance: data_ingestion_gcs_dag.local_to_gcs_task scheduled__2022-11-30T00:00:00+00:00 [running]> on host 2003d44c7bd2
[2022-12-01T06:01:33.255+0000] {taskinstance.py:1592} INFO - Exporting the following env vars:
AIRFLOW_CTX_DAG_OWNER=***
AIRFLOW_CTX_DAG_ID=data_ingestion_gcs_dag
AIRFLOW_CTX_TASK_ID=local_to_gcs_task
AIRFLOW_CTX_EXECUTION_DATE=2022-11-30T00:00:00+00:00
AIRFLOW_CTX_TRY_NUMBER=1
AIRFLOW_CTX_DAG_RUN_ID=scheduled__2022-11-30T00:00:00+00:00
[2022-12-01T06:01:33.290+0000] {taskinstance.py:1851} ERROR - Task failed with exception
Traceback (most recent call last):
  File "/home/airflow/.local/lib/python3.7/site-packages/airflow/operators/python.py", line 175, in execute
    return_value = self.execute_callable()
  File "/home/airflow/.local/lib/python3.7/site-packages/airflow/operators/python.py", line 193, in execute_callable
    return self.python_callable(*self.op_args, **self.op_kwargs)
  File "/opt/airflow/dags/data_ingestion_gcs_dag.py", line 51, in upload_to_gcs
    blob.upload_from_filename(local_file)
  File "/home/airflow/.local/lib/python3.7/site-packages/google/cloud/storage/blob.py", line 2735, in upload_from_filename
    retry=retry,
  File "/home/airflow/.local/lib/python3.7/site-packages/google/cloud/storage/blob.py", line 2594, in upload_from_file
    retry=retry,
  File "/home/airflow/.local/lib/python3.7/site-packages/google/cloud/storage/blob.py", line 2412, in _do_upload
    retry=retry,
  File "/home/airflow/.local/lib/python3.7/site-packages/google/cloud/storage/blob.py", line 2237, in _do_resumable_upload
    retry=retry,
  File "/home/airflow/.local/lib/python3.7/site-packages/google/cloud/storage/blob.py", line 2061, in _initiate_resumable_upload
    hostname=hostname, bucket_path=self.bucket.path
  File "/home/airflow/.local/lib/python3.7/site-packages/google/cloud/storage/bucket.py", line 1098, in path
    raise ValueError("Cannot determine path without bucket name.")
ValueError: Cannot determine path without bucket name.
[2022-12-01T06:01:33.306+0000] {taskinstance.py:1406} INFO - Marking task as UP_FOR_RETRY. dag_id=data_ingestion_gcs_dag, task_id=local_to_gcs_task, execution_date=20221130T000000, start_date=20221201T060132, end_date=20221201T060133
[2022-12-01T06:01:33.331+0000] {standard_task_runner.py:105} ERROR - Failed to execute job 8 for task local_to_gcs_task (Cannot determine path without bucket name.; 5823)
[2022-12-01T06:01:33.374+0000] {local_task_job.py:159} INFO - Task exited with return code 1
[2022-12-01T06:01:33.412+0000] {taskinstance.py:2623} INFO - 0 downstream tasks scheduled from follow-on schedule check
