[2023-01-06 08:30:42,146] {taskinstance.py:1032} INFO - Dependencies all met for <TaskInstance: yellow_taxi_data.download_dataset_task manual__2023-01-06T08:30:41.262614+00:00 [queued]>
[2023-01-06 08:30:42,158] {taskinstance.py:1032} INFO - Dependencies all met for <TaskInstance: yellow_taxi_data.download_dataset_task manual__2023-01-06T08:30:41.262614+00:00 [queued]>
[2023-01-06 08:30:42,159] {taskinstance.py:1238} INFO - 
--------------------------------------------------------------------------------
[2023-01-06 08:30:42,159] {taskinstance.py:1239} INFO - Starting attempt 1 of 2
[2023-01-06 08:30:42,159] {taskinstance.py:1240} INFO - 
--------------------------------------------------------------------------------
[2023-01-06 08:30:42,172] {taskinstance.py:1259} INFO - Executing <Task(BashOperator): download_dataset_task> on 2023-01-06 08:30:41.262614+00:00
[2023-01-06 08:30:42,179] {standard_task_runner.py:52} INFO - Started process 3471 to run task
[2023-01-06 08:30:42,184] {standard_task_runner.py:76} INFO - Running: ['***', 'tasks', 'run', 'yellow_taxi_data', 'download_dataset_task', 'manual__2023-01-06T08:30:41.262614+00:00', '--job-id', '24', '--raw', '--subdir', 'DAGS_FOLDER/ingestion_dag.py', '--cfg-path', '/tmp/tmp_39eki1z', '--error-file', '/tmp/tmpygfkehve']
[2023-01-06 08:30:42,185] {standard_task_runner.py:77} INFO - Job 24: Subtask download_dataset_task
[2023-01-06 08:30:42,257] {logging_mixin.py:109} INFO - Running <TaskInstance: yellow_taxi_data.download_dataset_task manual__2023-01-06T08:30:41.262614+00:00 [running]> on host 5d77b11d05f0
[2023-01-06 08:30:42,308] {warnings.py:110} WARNING - /home/***/.local/lib/python3.7/site-packages/***/utils/context.py:152: AirflowContextDeprecationWarning: Accessing 'execution_date' from the template is deprecated and will be removed in a future version. Please use 'data_interval_start' or 'logical_date' instead.
  warnings.warn(_create_deprecation_warning(key, self._deprecation_replacements[key]))

[2023-01-06 08:30:42,335] {taskinstance.py:1426} INFO - Exporting the following env vars:
AIRFLOW_CTX_DAG_OWNER=***
AIRFLOW_CTX_DAG_ID=yellow_taxi_data
AIRFLOW_CTX_TASK_ID=download_dataset_task
AIRFLOW_CTX_EXECUTION_DATE=2023-01-06T08:30:41.262614+00:00
AIRFLOW_CTX_DAG_RUN_ID=manual__2023-01-06T08:30:41.262614+00:00
[2023-01-06 08:30:42,337] {subprocess.py:62} INFO - Tmp dir root location: 
 /tmp
[2023-01-06 08:30:42,338] {subprocess.py:74} INFO - Running command: ['bash', '-c', 'curl -sSLf https://d37ci6vzurychx.cloudfront.net/trip-data/yellow_tripdata_2023-01.parquet > /opt/***/yellow_tripdata_2023-01.parquet']
[2023-01-06 08:30:42,353] {subprocess.py:85} INFO - Output:
[2023-01-06 08:30:42,788] {subprocess.py:89} INFO - curl: (22) The requested URL returned error: 403
[2023-01-06 08:30:42,790] {subprocess.py:93} INFO - Command exited with return code 22
[2023-01-06 08:30:42,809] {taskinstance.py:1700} ERROR - Task failed with exception
Traceback (most recent call last):
  File "/home/airflow/.local/lib/python3.7/site-packages/airflow/models/taskinstance.py", line 1329, in _run_raw_task
    self._execute_task_with_callbacks(context)
  File "/home/airflow/.local/lib/python3.7/site-packages/airflow/models/taskinstance.py", line 1455, in _execute_task_with_callbacks
    result = self._execute_task(context, self.task)
  File "/home/airflow/.local/lib/python3.7/site-packages/airflow/models/taskinstance.py", line 1511, in _execute_task
    result = execute_callable(context=context)
  File "/home/airflow/.local/lib/python3.7/site-packages/airflow/operators/bash.py", line 188, in execute
    f'Bash command failed. The command returned a non-zero exit code {result.exit_code}.'
airflow.exceptions.AirflowException: Bash command failed. The command returned a non-zero exit code 22.
[2023-01-06 08:30:42,818] {taskinstance.py:1277} INFO - Marking task as UP_FOR_RETRY. dag_id=yellow_taxi_data, task_id=download_dataset_task, execution_date=20230106T083041, start_date=20230106T083042, end_date=20230106T083042
[2023-01-06 08:30:42,835] {standard_task_runner.py:92} ERROR - Failed to execute job 24 for task download_dataset_task
Traceback (most recent call last):
  File "/home/airflow/.local/lib/python3.7/site-packages/airflow/task/task_runner/standard_task_runner.py", line 85, in _start_by_fork
    args.func(args, dag=self.dag)
  File "/home/airflow/.local/lib/python3.7/site-packages/airflow/cli/cli_parser.py", line 48, in command
    return func(*args, **kwargs)
  File "/home/airflow/.local/lib/python3.7/site-packages/airflow/utils/cli.py", line 92, in wrapper
    return f(*args, **kwargs)
  File "/home/airflow/.local/lib/python3.7/site-packages/airflow/cli/commands/task_command.py", line 298, in task_run
    _run_task_by_selected_method(args, dag, ti)
  File "/home/airflow/.local/lib/python3.7/site-packages/airflow/cli/commands/task_command.py", line 107, in _run_task_by_selected_method
    _run_raw_task(args, ti)
  File "/home/airflow/.local/lib/python3.7/site-packages/airflow/cli/commands/task_command.py", line 184, in _run_raw_task
    error_file=args.error_file,
  File "/home/airflow/.local/lib/python3.7/site-packages/airflow/utils/session.py", line 70, in wrapper
    return func(*args, session=session, **kwargs)
  File "/home/airflow/.local/lib/python3.7/site-packages/airflow/models/taskinstance.py", line 1329, in _run_raw_task
    self._execute_task_with_callbacks(context)
  File "/home/airflow/.local/lib/python3.7/site-packages/airflow/models/taskinstance.py", line 1455, in _execute_task_with_callbacks
    result = self._execute_task(context, self.task)
  File "/home/airflow/.local/lib/python3.7/site-packages/airflow/models/taskinstance.py", line 1511, in _execute_task
    result = execute_callable(context=context)
  File "/home/airflow/.local/lib/python3.7/site-packages/airflow/operators/bash.py", line 188, in execute
    f'Bash command failed. The command returned a non-zero exit code {result.exit_code}.'
airflow.exceptions.AirflowException: Bash command failed. The command returned a non-zero exit code 22.
[2023-01-06 08:30:42,880] {local_task_job.py:154} INFO - Task exited with return code 1
[2023-01-06 08:30:42,927] {local_task_job.py:264} INFO - 0 downstream tasks scheduled from follow-on schedule check
